OrderBookSim/OrderBookSim/Outputs/Log1359736497.txt
0--INFO	Added rule
0--INFO	Added rule
0--INFO	Added rule
0--INFO	Added rule
0--INFO	Added trader: Trader[0]: Cash[$4964.75], Holding:GOOG[470], PositionCash[$4964.75], PositionHolding:GOOG[470]
0--INFO	Added trader: Trader[1]: Cash[$10222.48], Holding:GOOG[4232], PositionCash[$10222.48], PositionHolding:GOOG[4232]
0--INFO	Added trader: Trader[2]: Cash[$2136.30], Holding:GOOG[1683], PositionCash[$2136.30], PositionHolding:GOOG[1683]
0--INFO	Added trader: Trader[3]: Cash[$11897.95], Holding:GOOG[10576], PositionCash[$11897.95], PositionHolding:GOOG[10576]
0--INFO	Added trader: Trader[4]: Cash[$19083.83], Holding:GOOG[18295], PositionCash[$19083.83], PositionHolding:GOOG[18295]
0--INFO	Added trader: Trader[5]: Cash[$5789.36], Holding:GOOG[16936], PositionCash[$5789.36], PositionHolding:GOOG[16936]
0--INFO	Added trader: Trader[6]: Cash[$4090.70], Holding:GOOG[16908], PositionCash[$4090.70], PositionHolding:GOOG[16908]
0--INFO	Added trader: Trader[7]: Cash[$13834.04], Holding:GOOG[19365], PositionCash[$13834.04], PositionHolding:GOOG[19365]
0--INFO	Added trader: Trader[8]: Cash[$16429.33], Holding:GOOG[5634], PositionCash[$16429.33], PositionHolding:GOOG[5634]
0--INFO	Added trader: Trader[9]: Cash[$1870.17], Holding:GOOG[1711], PositionCash[$1870.17], PositionHolding:GOOG[1711]
0--INFO	Added trader: Trader[10]: Cash[$6567.58], Holding:GOOG[2430], PositionCash[$6567.58], PositionHolding:GOOG[2430]
0--INFO	Added trader: Trader[11]: Cash[$16411.63], Holding:GOOG[2726], PositionCash[$16411.63], PositionHolding:GOOG[2726]
0--INFO	Added trader: Trader[12]: Cash[$13747.37], Holding:GOOG[12004], PositionCash[$13747.37], PositionHolding:GOOG[12004]
0--INFO	Added trader: Trader[13]: Cash[$9726.86], Holding:GOOG[1360], PositionCash[$9726.86], PositionHolding:GOOG[1360]
0--INFO	Added trader: Trader[14]: Cash[$3452.86], Holding:GOOG[18615], PositionCash[$3452.86], PositionHolding:GOOG[18615]
0--INFO	Added trader: Trader[15]: Cash[$9294.11], Holding:GOOG[7088], PositionCash[$9294.11], PositionHolding:GOOG[7088]
0--INFO	Added trader: Trader[16]: Cash[$16458.02], Holding:GOOG[14811], PositionCash[$16458.02], PositionHolding:GOOG[14811]
0--INFO	Added trader: Trader[17]: Cash[$1913.51], Holding:GOOG[19347], PositionCash[$1913.51], PositionHolding:GOOG[19347]
0--INFO	Added trader: Trader[18]: Cash[$16118.66], Holding:GOOG[1024], PositionCash[$16118.66], PositionHolding:GOOG[1024]
0--INFO	Added trader: Trader[19]: Cash[$16756.49], Holding:GOOG[18332], PositionCash[$16756.49], PositionHolding:GOOG[18332]
0--INFO	Added trader: Trader[20]: Cash[$4100.47], Holding:GOOG[503], PositionCash[$4100.47], PositionHolding:GOOG[503]
0--INFO	Added trader: Trader[21]: Cash[$4964.75], Holding:GOOG[470], PositionCash[$4964.75], PositionHolding:GOOG[470]
0--INFO	Added trader: Trader[22]: Cash[$4964.75], Holding:GOOG[470], PositionCash[$4964.75], PositionHolding:GOOG[470]
0--INFO	Added trader: Trader[23]: Cash[$4964.75], Holding:GOOG[470], PositionCash[$4964.75], PositionHolding:GOOG[470]
0--INFO	Added trader: Trader[24]: Cash[$4964.75], Holding:GOOG[470], PositionCash[$4964.75], PositionHolding:GOOG[470]
0--INFO	Added trader: Trader[25]: Cash[$4964.75], Holding:GOOG[470], PositionCash[$4964.75], PositionHolding:GOOG[470]
0--INFO	Added trader: Trader[26]: Cash[$4964.75], Holding:GOOG[470], PositionCash[$4964.75], PositionHolding:GOOG[470]
0--INFO	Added trader: Trader[27]: Cash[$4964.75], Holding:GOOG[470], PositionCash[$4964.75], PositionHolding:GOOG[470]
0--INFO	Added trader: Trader[28]: Cash[$4964.75], Holding:GOOG[470], PositionCash[$4964.75], PositionHolding:GOOG[470]
0--INFO	Added trader: Trader[29]: Cash[$4964.75], Holding:GOOG[470], PositionCash[$4964.75], PositionHolding:GOOG[470]
0--INFO	Added trader: Trader[30]: Cash[$1000000.00], Holding:GOOG[10000000], PositionCash[$1000000.00], PositionHolding:GOOG[10000000]
0--INFO	Added trader: Trader[31]: Cash[$1000000.00], Holding:GOOG[10000000], PositionCash[$1000000.00], PositionHolding:GOOG[10000000]
0--INFO	Added trader: Trader[32]: Cash[$1000000.00], Holding:GOOG[10000000], PositionCash[$1000000.00], PositionHolding:GOOG[10000000]
0--INFO	Added trader: Trader[33]: Cash[$1000000.00], Holding:GOOG[10000000], PositionCash[$1000000.00], PositionHolding:GOOG[10000000]
0--INFO	Added trader: Trader[34]: Cash[$1000000.00], Holding:GOOG[10000000], PositionCash[$1000000.00], PositionHolding:GOOG[10000000]
42--INFO	Enqueued order: Price: 0.00, Volume: 940, Type: SELL, Market Order: 1, Participant: 21, Stock:[ID: 0, Symbol: GOOG], Time: 42, OrderNumber: 0
42--INFO	Enqueued order: Price: 2147483647.00, Volume: 107, Type: BUY, Market Order: 1, Participant: 22, Stock:[ID: 0, Symbol: GOOG], Time: 42, OrderNumber: 1
42--INFO	Enqueued order: Price: 0.00, Volume: 529, Type: SELL, Market Order: 1, Participant: 23, Stock:[ID: 0, Symbol: GOOG], Time: 42, OrderNumber: 2
42--INFO	Enqueued order: Price: 2147483647.00, Volume: 284, Type: BUY, Market Order: 1, Participant: 24, Stock:[ID: 0, Symbol: GOOG], Time: 42, OrderNumber: 3
42--INFO	Enqueued order: Price: 0.00, Volume: 205, Type: SELL, Market Order: 1, Participant: 25, Stock:[ID: 0, Symbol: GOOG], Time: 42, OrderNumber: 4
42--INFO	Enqueued order: Price: 2147483647.00, Volume: 969, Type: BUY, Market Order: 1, Participant: 26, Stock:[ID: 0, Symbol: GOOG], Time: 42, OrderNumber: 5
42--INFO	Enqueued order: Price: 0.00, Volume: 603, Type: SELL, Market Order: 1, Participant: 27, Stock:[ID: 0, Symbol: GOOG], Time: 42, OrderNumber: 6
42--INFO	Enqueued order: Price: 100.07, Volume: 329, Type: SELL, Market Order: 0, Participant: 28, Stock:[ID: 0, Symbol: GOOG], Time: 42, OrderNumber: 7
42--INFO	Enqueued order: Price: 0.00, Volume: 137, Type: SELL, Market Order: 1, Participant: 29, Stock:[ID: 0, Symbol: GOOG], Time: 42, OrderNumber: 8
44--INFO	Last Price Set:100.00
44--INFO	Notified Traders of trade44---Trade ID: 0, Price: 100.00, Volume: 107 between ID:[22] and ID:[21]
46--INFO	Last Price Set:100.00
46--INFO	Notified Traders of trade46---Trade ID: 1, Price: 100.00, Volume: 284 between ID:[24] and ID:[21]
48--INFO	Last Price Set:100.00
48--INFO	Notified Traders of trade48---Trade ID: 2, Price: 100.00, Volume: 549 between ID:[26] and ID:[21]
48--INFO	Last Price Set:100.00
48--INFO	Notified Traders of trade48---Trade ID: 3, Price: 100.00, Volume: 420 between ID:[26] and ID:[23]
77--INFO	Enqueued order: Price: 2147483647.00, Volume: 6, Type: BUY, Market Order: 1, Participant: 20, Stock:[ID: 0, Symbol: GOOG], Time: 77, OrderNumber: 9
78--INFO	Last Price Set:100.00
78--INFO	Notified Traders of trade78---Trade ID: 4, Price: 100.00, Volume: 6 between ID:[20] and ID:[23]
84--INFO	Enqueued order: Price: 100.04, Volume: 173, Type: SELL, Market Order: 0, Participant: 21, Stock:[ID: 0, Symbol: GOOG], Time: 84, OrderNumber: 10
84--INFO	Enqueued order: Price: 2147483647.00, Volume: 355, Type: BUY, Market Order: 1, Participant: 22, Stock:[ID: 0, Symbol: GOOG], Time: 84, OrderNumber: 11
84--INFO	Enqueued order: Price: 0.00, Volume: 333, Type: SELL, Market Order: 1, Participant: 23, Stock:[ID: 0, Symbol: GOOG], Time: 84, OrderNumber: 12
84--INFO	Enqueued order: Price: 0.00, Volume: 806, Type: SELL, Market Order: 1, Participant: 24, Stock:[ID: 0, Symbol: GOOG], Time: 84, OrderNumber: 13
84--INFO	Enqueued order: Price: 0.00, Volume: 917, Type: SELL, Market Order: 1, Participant: 25, Stock:[ID: 0, Symbol: GOOG], Time: 84, OrderNumber: 14
84--INFO	Enqueued order: Price: 0.00, Volume: 356, Type: SELL, Market Order: 1, Participant: 26, Stock:[ID: 0, Symbol: GOOG], Time: 84, OrderNumber: 15
84--INFO	Enqueued order: Price: 2147483647.00, Volume: 457, Type: BUY, Market Order: 1, Participant: 27, Stock:[ID: 0, Symbol: GOOG], Time: 84, OrderNumber: 16
84--INFO	Enqueued order: Price: 2147483647.00, Volume: 178, Type: BUY, Market Order: 1, Participant: 28, Stock:[ID: 0, Symbol: GOOG], Time: 84, OrderNumber: 17
84--INFO	Enqueued order: Price: 100.04, Volume: 389, Type: SELL, Market Order: 0, Participant: 29, Stock:[ID: 0, Symbol: GOOG], Time: 84, OrderNumber: 18
