OrderBookSim/OrderBookSim/Outputs/Output1359736497.txt
0,100,0,0,0
1,100,0,0,0
2,100,0,0,0
3,100,0,0,0
4,100,0,0,0
5,100,0,0,0
6,100,0,0,0
7,100,0,0,0
8,100,0,0,0
9,100,0,0,0
10,100,0,0,0
11,100,0,0,0
12,100,0,0,0
13,100,0,0,0
14,100,0,0,0
15,100,0,0,0
16,100,0,0,0
17,100,0,0,0
18,100,0,0,0
19,100,0,0,0
20,100,0,0,0
21,100,0,0,0
22,100,0,0,0
23,100,0,0,0
24,100,0,0,0
25,100,0,0,0
26,100,0,0,0
27,100,0,0,0
28,100,0,0,0
29,100,0,0,0
30,100,0,0,0
31,100,0,0,0
32,100,0,0,0
33,100,0,0,0
34,100,0,0,0
35,100,0,0,0
36,100,0,0,0
37,100,0,0,0
38,100,0,0,0
39,100,0,0,0
40,100,0,0,0
41,100,0,0,0
42,100,0,0,0
43,100,0,1,0
44,100,0,1,1
45,100,0,2,1
46,100,0,2,2
47,100,0,3,2
48,100,0,2,4
49,100,0,3,4
50,100,0,4,4
51,100,0,5,4
52,100,0,5,4
53,100,0,5,4
54,100,0,5,4
55,100,0,5,4
56,100,0,5,4
57,100,0,5,4
58,100,0,5,4
59,100,0,5,4
60,100,0,5,4
61,100,0,5,4
62,100,0,5,4
63,100,0,5,4
64,100,0,5,4
65,100,0,5,4
66,100,0,5,4
67,100,0,5,4
68,100,0,5,4
69,100,0,5,4
70,100,0,5,4
71,100,0,5,4
72,100,0,5,4
73,100,0,5,4
74,100,0,5,4
75,100,0,5,4
76,100,0,5,4
77,100,0,5,4
78,100,0,5,5
79,100,0,5,5
80,100,0,5,5
81,100,0,5,5
82,100,0,5,5
83,100,0,5,5
84,100,0,5,5
85,100,0,6,5
86,100,0,4,8
87,100,0,5,8
88,100,0,6,8
89,100,0,7,8
90,100,0,8,8
91,100,0,7,10
92,100,0,7,11
93,100,0,8,11
94,100,0,8,11
95,100,0,8,11
96,100,0,8,11
97,100,0,8,11
98,100,0,8,11
99,100,0,8,11
100,100,0,8,11
101,100,0,8,11
102,100,0,8,11
103,100,0,8,11
104,100,0,8,11
105,100,0,8,11
106,100,0,8,11
107,100,0,8,11
108,100,0,8,11
109,100,0,8,11
110,100,0,8,11
111,100,0,8,11
112,100,0,8,11
113,100,0,8,11
114,100,0,8,11
115,100,0,8,11
116,100,0,8,11
117,100,0,8,11
118,100,0,8,11
119,100,0,8,11
120,100,0,8,11
121,100,0,8,11
122,100,0,8,11
123,100,0,8,11
124,100,0,8,11
125,100,0,8,11
126,100,0,8,11
127,100,0,9,11
128,100,0,10,11
129,100,0,11,11
130,100,0,12,11
131,100,0,13,11
132,100,0,13,12
133,100,0,12,14
134,100,0,10,17
135,100,0,9,19
136,99.99,0,9,20
137,99.99,0,9,20
138,99.99,0,9,20
139,99.99,0,9,20
140,99.99,0,9,20
141,99.99,0,9,20
142,99.99,0,9,20
143,99.99,0,9,20
144,99.99,0,9,20
145,99.99,0,9,20
146,99.99,0,9,20
147,99.99,0,9,20
148,99.99,0,9,20
149,99.99,0,9,20
150,99.99,0,9,20
151,99.99,0,9,20
152,99.99,0,9,20
153,99.99,0,9,20
154,99.99,0,9,20
155,99.99,0,10,20
156,99.99,0,10,20
157,99.99,0,10,20
158,99.99,0,10,20
159,99.99,0,10,20
160,99.99,0,10,20
161,99.99,0,10,20
162,99.99,0,10,20
163,99.99,0,10,20
164,99.99,0,10,20
165,99.99,0,10,20
166,99.99,0,10,20
167,99.99,0,10,20
168,99.99,0,10,20
169,99.99,0,9,22
170,99.99,0,8,24
171,99.99,0,8,25
172,100.02,0,5,29
173,100.04,0,4,31
174,100.04,0,3,33
175,100.04,0,2,35
176,100.04,0,2,36
177,100.04,0,2,37
178,100.04,0,2,37
179,100.04,0,2,37
180,100.04,0,2,37
181,100.04,0,2,37
182,100.04,0,2,37
183,100.04,0,2,37
184,100.04,0,2,37
185,100.04,0,2,37
186,100.04,0,2,37
187,100.04,0,2,37
188,100.04,0,2,37
189,100.04,0,2,37
190,100.04,0,2,37
191,100.04,0,2,37
192,100.04,0,2,37
193,100.04,0,2,37
194,100.04,0,2,37
195,100.04,0,2,37
196,100.04,0,2,37
197,100.04,0,2,37
198,100.04,0,2,37
199,100.04,0,2,37
200,100.04,0,2,37
201,100.04,0,2,37
202,100.04,0,2,37
203,100.04,0,2,37
204,100.04,0,2,37
205,100.04,0,2,37
206,100.04,0,2,37
207,100.04,0,2,37
208,100.04,0,2,37
209,100.04,0,2,37
210,100.04,0,2,37
211,100.04,0,3,37
212,100.04,1,3,37
213,100.07,1,1,40
214,100.07,1,2,40
215,100.02,0,3,41
216,100.02,0,4,41
217,100.02,0,5,41
218,100.02,0,6,41
219,100.02,0,5,43
220,100.02,0,5,43
221,100.02,0,5,43
222,100.02,0,5,43
223,100.02,0,5,43
224,100.02,0,5,43
225,100.02,0,5,43
226,100.02,0,5,43
227,100.02,0,5,43
228,100.02,0,5,43
229,100.02,0,5,43
230,100.02,0,5,43
231,100.02,0,5,43
232,100.02,0,4,45
233,100.02,0,4,45
234,100.02,0,4,45
235,100.02,0,4,45
236,100.02,0,4,45
237,100.02,0,4,45
238,100.02,0,4,45
239,100.02,0,4,45
240,100.02,0,4,45
241,100.02,0,4,45
242,100.02,0,4,45
243,100.02,0,4,45
244,100.02,0,4,45
245,100.02,0,4,45
246,100.02,0,4,45
247,100.02,0,4,45
248,100.02,0,4,45
249,100.02,0,4,45
250,100.02,0,4,45
251,100.02,0,4,45
252,100.02,0,4,45
253,100.06,0,3,47
254,100.06,0,4,47
255,100.06,0,5,47
256,100.06,0,6,47
257,100.06,0,7,47
258,100.06,0,7,48
259,100.06,0,8,48
260,100.06,0,6,51
261,100.06,0,7,51
262,100.06,0,7,51
263,100.06,0,7,51
264,100.06,0,7,51
265,100.06,0,7,51
266,100.06,0,7,51
267,100.06,0,7,51
268,100.06,0,7,51
269,100.06,0,7,51
270,100.06,0,7,51
271,100.06,0,7,51
272,100.06,0,7,51
273,100.06,0,7,51
274,100.06,0,7,51
275,100.06,0,7,51
276,100.06,0,7,51
277,100.06,0,7,51
278,100.06,0,7,51
279,100.06,0,7,51
280,100.06,0,7,51
281,100.06,0,7,51
282,100.06,0,7,51
283,100.06,0,7,51
284,100.06,0,7,51
285,100.06,0,7,51
286,100.06,0,7,51
287,100.06,0,7,51
288,100.06,0,7,51
289,100.06,0,7,51
290,100.06,0,7,51
291,100.06,0,7,51
292,100.06,0,7,51
293,100.06,0,7,51
294,100.06,0,7,51
295,100.06,0,7,52
296,100.06,0,8,52
297,100.06,0,7,54
298,100.06,0,6,56
299,100.06,0,7,56
300,100.06,0,8,56
301,100.06,0,9,56
302,100.06,0,10,56
303,100.06,0,11,56
304,100.06,0,11,56
305,100.06,0,11,56
306,100.06,0,11,56
307,100.06,0,11,56
308,100.06,0,11,56
309,100.06,0,12,56
310,100.06,0,12,56
311,100.06,0,12,56
312,100.06,0,12,56
313,100.06,0,12,56
314,100.06,0,12,56
315,100.06,0,12,56
316,100.06,0,12,56
317,100.06,0,12,56
318,100.06,0,12,56
319,100.06,0,12,56
320,100.06,0,12,56
321,100.06,0,12,56
322,100.06,0,12,56
323,100.06,0,12,56
324,100.06,0,12,56
325,100.06,0,12,56
326,100.06,0,12,56
327,100.06,0,12,56
328,100.06,0,12,56
329,100.06,0,12,56
330,100.06,0,12,56
331,100.06,0,12,56
332,100.06,0,12,56
333,100.06,0,12,56
334,100.06,0,12,56
335,100.06,0,12,56
336,100.06,0,12,56
337,100.06,0,11,58
338,100.06,0,12,58
339,100.06,0,11,60
340,100.05,0,10,62
341,100.05,0,11,62
342,100.05,0,12,62
343,100.05,0,11,64
344,100.05,0,12,64
345,100.04,0,12,65
346,100.04,0,13,65
347,100.04,0,14,65
348,100.04,0,15,65
349,100.04,0,16,65
350,100.04,0,17,65
351,100.04,0,18,65
352,100.04,0,19,65
353,100.04,0,20,65
354,100.04,0,20,65
355,100.04,0,20,65
356,100.04,0,20,65
357,100.04,0,20,65
358,100.04,0,20,65
359,100.04,0,20,65
360,100.04,0,20,65
361,100.04,0,20,65
362,100.04,0,20,65
363,100.04,0,20,65
364,100.04,0,20,65
365,100.04,0,20,65
366,100.04,0,20,65
367,100.04,0,20,65
368,100.04,0,20,65
369,100.04,0,20,65
370,100.04,0,20,65
371,100.04,0,20,65
372,100.04,0,20,65
373,100.04,0,20,65
374,100.04,0,20,65
375,100.04,0,20,65
376,100.04,0,20,65
377,100.04,0,20,65
378,100.04,0,20,65
379,100.04,0,17,69
380,100.04,0,17,70
381,100.04,0,16,72
382,100.04,0,17,72
383,100.04,0,18,72
384,100.04,0,17,74
385,100.04,0,14,78
386,99.98,1,12,80
387,99.98,1,12,81
388,100.04,1,9,85
389,100.04,1,9,85
390,100.04,1,9,85
391,100.04,1,9,85
392,100.04,1,9,85
393,100.04,1,9,85
394,100.04,1,9,85
395,100.04,1,9,85
396,100.04,1,9,85
397,100.04,1,9,85
398,100.04,1,9,85
399,100.04,1,9,85
400,100.04,1,9,85
401,100.04,1,9,85
402,100.04,1,9,85
403,100.04,1,9,85
404,100.04,1,9,85
405,100.04,1,9,85
406,100.04,1,9,85
407,100.04,1,9,85
408,100.04,1,9,85
409,100.04,1,9,85
410,100.04,1,9,85
411,100.04,1,9,85
412,100.04,1,9,85
413,100.04,1,9,85
414,100.04,1,9,85
415,100.04,1,9,85
416,100.04,1,9,85
417,100.04,1,9,85
418,100.04,1,9,85
419,100.04,1,9,85
420,100.04,1,9,85
421,100.04,1,9,86
422,100.04,1,9,87
423,100.04,1,8,89
424,100.04,2,8,89
425,99.97,1,8,91
426,99.97,0,9,92
427,100.04,0,8,94
428,100.04,0,9,94
429,100.04,0,10,94
430,100.04,0,10,94
431,100.04,0,10,94
432,100.04,0,10,94
433,100.04,0,10,94
434,100.04,0,10,94
435,100.04,0,10,94
436,100.04,0,10,94
437,100.04,0,10,94
438,100.04,0,10,94
439,100.04,0,10,94
440,100.04,0,10,94
441,100.04,0,10,94
442,100.04,0,10,94
443,100.04,0,10,94
444,100.04,0,10,94
445,100.04,0,10,94
446,100.04,0,10,94
447,100.04,0,10,94
448,100.04,0,10,94
449,100.04,0,10,94
450,100.04,0,10,94
451,100.07,1,0,104
452,100.07,0,1,105
453,100.07,1,0,106
454,100.07,0,1,107
455,100.07,1,0,108
456,100.07,1,0,108
457,100.07,1,0,108
458,100.07,1,0,108
459,100.07,1,0,108
460,100.07,1,0,108
461,100.07,1,0,108
462,100.07,1,0,108
463,100.07,2,0,108
464,100.14,2,0,109
465,100.14,3,0,109
466,100.14,3,0,110
467,100.14,3,0,111
468,100.14,4,0,111
469,100.14,4,0,112
470,100.14,4,0,113
471,100.14,5,0,113
472,100.14,6,0,113
